<?xml version="1.0" encoding="utf-8"?>
<!-- =================================================================================== -->
<!-- |    This document was autogenerated by xacro from adaption_finger.xacro          | -->
<!-- |    EDITING THIS FILE BY HAND IS NOT RECOMMENDED                                 | -->
<!-- =================================================================================== -->
<robot name="adaption_finger">
  <link name="finger_base_link">
    <inertial>
      <origin rpy="0 0 0" xyz="2.1684E-19 1.7347E-18 0.0012139"/>
      <mass value="0.00063708"/>
      <inertia ixx="0" ixy="0" ixz="0" iyy="0" iyz="0" izz="0"/>
    </inertial>
    <visual>
      <origin rpy="0 0 0" xyz="0 0 0"/>
      <geometry>
        <mesh filename="package://adaption_finger/meshes/base_link.STL"/>
      </geometry>
      <material name="">
        <color rgba="0.75294 0.75294 0.75294 1"/>
      </material>
    </visual>
    <collision>
      <origin rpy="0 0 0" xyz="0 0 0"/>
      <geometry>
        <mesh filename="package://adaption_finger/meshes/base_link.STL"/>
      </geometry>
    </collision>
  </link>
  <link name="upper_link">
    <inertial>
      <origin rpy="0 0 0" xyz="4.3368E-18 1.7347E-18 -0.02"/>
      <mass value="0.0036771"/>
      <inertia ixx="0" ixy="0" ixz="0" iyy="0" iyz="0" izz="0"/>
    </inertial>
    <visual>
      <origin rpy="0 0 0" xyz="0 0 0"/>
      <geometry>
        <mesh filename="package://adaption_finger/meshes/upper_link.STL"/>
      </geometry>
      <material name="">
        <color rgba="0.75294 0.75294 0.75294 1"/>
      </material>
    </visual>
    <collision>
      <origin rpy="0 0 0" xyz="0 0 0"/>
      <geometry>
        <mesh filename="package://adaption_finger/meshes/upper_link.STL"/>
      </geometry>
    </collision>
  </link>
  <joint name="tail_joint" type="continuous">
    <origin rpy="0 0 0" xyz="0 0 0"/>
    <parent link="finger_base_link"/>
    <child link="upper_link"/>
    <axis xyz="0 -1 0"/>
  </joint>
  <link name="tip_link">
    <inertial>
      <origin rpy="0 0 0" xyz="5.2042E-18 1.7347E-18 -0.02"/>
      <mass value="0.0035142"/>
      <inertia ixx="0" ixy="0" ixz="0" iyy="0" iyz="0" izz="0"/>
    </inertial>
    <visual>
      <origin rpy="0 0 0" xyz="0 0 0"/>
      <geometry>
        <mesh filename="package://adaption_finger/meshes/tip_link.STL"/>
      </geometry>
      <material name="">
        <color rgba="0.75294 0.75294 0.75294 1"/>
      </material>
    </visual>
    <collision>
      <origin rpy="0 0 0" xyz="0 0 0"/>
      <geometry>
        <mesh filename="package://adaption_finger/meshes/tip_link.STL"/>
      </geometry>
    </collision>
  </link>
  <joint name="tip_joint" type="continuous">
    <origin rpy="0 0 0" xyz="0 0 -0.04"/>
    <parent link="upper_link"/>
    <child link="tip_link"/>
    <axis xyz="0 -1 0"/>
  </joint>
</robot>

